Workbook

Sheet 等级-经验对照
A1: 等级-经验对照
A3: 等级 | B3: 累计经验 | C3: 下一级经验
A4: 1 | B4: =ROUND(IF(A4<=参数说明!$A$14,FORECAST(A4,参数说明!$B$13:$B$14,参数说明!$A$13:$A$14),IF(A4<=参数说明!$A$15,FORECAST(A4,参数说明!$B$14:$B$15,参数说明!$A$14:$A$15),IF(A4<=参数说明!$A$16,FORECAST(A4,参数说明!$B$15:$B$16,参数说明!$A$15:$A$16),IF(A4<=参数说明!$A$17,FORECAST(A4,参数说明!$B$16:$B$17,参数说明!$A$16:$A$17),IF(A4<=参数说明!$A$18,FORECAST(A4,参数说明!$B$17:$B$18,参数说明!$A$17:$A$18),IF(A4<=参数说明!$A$19,FORECAST(A4,参数说明!$B$18:$B$19,参数说明!$A$18:$A$19),FORECAST(A4,参数说明!$B$19:$B$20,参数说明!$A$19:$A$20)))))))/5,0)*5 -> 10 | C4: =B5-B4 -> 10
A5: 2 | B5: =ROUND(IF(A5<=参数说明!$A$14,FORECAST(A5,参数说明!$B$13:$B$14,参数说明!$A$13:$A$14),IF(A5<=参数说明!$A$15,FORECAST(A5,参数说明!$B$14:$B$15,参数说明!$A$14:$A$15),IF(A5<=参数说明!$A$16,FORECAST(A5,参数说明!$B$15:$B$16,参数说明!$A$15:$A$16),IF(A5<=参数说明!$A$17,FORECAST(A5,参数说明!$B$16:$B$17,参数说明!$A$16:$A$17),IF(A5<=参数说明!$A$18,FORECAST(A5,参数说明!$B$17:$B$18,参数说明!$A$17:$A$18),IF(A5<=参数说明!$A$19,FORECAST(A5,参数说明!$B$18:$B$19,参数说明!$A$18:$A$19),FORECAST(A5,参数说明!$B$19:$B$20,参数说明!$A$19:$A$20)))))))/5,0)*5 -> 20 | C5: =B6-B5 -> 10
A6: 3 | B6: =ROUND(IF(A6<=参数说明!$A$14,FORECAST(A6,参数说明!$B$13:$B$14,参数说明!$A$13:$A$14),IF(A6<=参数说明!$A$15,FORECAST(A6,参数说明!$B$14:$B$15,参数说明!$A$14:$A$15),IF(A6<=参数说明!$A$16,FORECAST(A6,参数说明!$B$15:$B$16,参数说明!$A$15:$A$16),IF(A6<=参数说明!$A$17,FORECAST(A6,参数说明!$B$16:$B$17,参数说明!$A$16:$A$17),IF(A6<=参数说明!$A$18,FORECAST(A6,参数说明!$B$17:$B$18,参数说明!$A$17:$A$18),IF(A6<=参数说明!$A$19,FORECAST(A6,参数说明!$B$18:$B$19,参数说明!$A$18:$A$19),FORECAST(A6,参数说明!$B$19:$B$20,参数说明!$A$19:$A$20)))))))/5,0)*5 -> 30 | C6: =B7-B6 -> 30
A7: 4 | B7: =ROUND(IF(A7<=参数说明!$A$14,FORECAST(A7,参数说明!$B$13:$B$14,参数说明!$A$13:$A$14),IF(A7<=参数说明!$A$15,FORECAST(A7,参数说明!$B$14:$B$15,参数说明!$A$14:$A$15),IF(A7<=参数说明!$A$16,FORECAST(A7,参数说明!$B$15:$B$16,参数说明!$A$15:$A$16),IF(A7<=参数说明!$A$17,FORECAST(A7,参数说明!$B$16:$B$17,参数说明!$A$16:$A$17),IF(A7<=参数说明!$A$18,FORECAST(A7,参数说明!$B$17:$B$18,参数说明!$A$17:$A$18),IF(A7<=参数说明!$A$19,FORECAST(A7,参数说明!$B$18:$B$19,参数说明!$A$18:$A$19),FORECAST(A7,参数说明!$B$19:$B$20,参数说明!$A$19:$A$20)))))))/5,0)*5 -> 60 | C7: =B8-B7 -> 25
A8: 5 | B8: =ROUND(IF(A8<=参数说明!$A$14,FORECAST(A8,参数说明!$B$13:$B$14,参数说明!$A$13:$A$14),IF(A8<=参数说明!$A$15,FORECAST(A8,参数说明!$B$14:$B$15,参数说明!$A$14:$A$15),IF(A8<=参数说明!$A$16,FORECAST(A8,参数说明!$B$15:$B$16,参数说明!$A$15:$A$16),IF(A8<=参数说明!$A$17,FORECAST(A8,参数说明!$B$16:$B$17,参数说明!$A$16:$A$17),IF(A8<=参数说明!$A$18,FORECAST(A8,参数说明!$B$17:$B$18,参数说明!$A$17:$A$18),IF(A8<=参数说明!$A$19,FORECAST(A8,参数说明!$B$18:$B$19,参数说明!$A$18:$A$19),FORECAST(A8,参数说明!$B$19:$B$20,参数说明!$A$19:$A$20)))))))/5,0)*5 -> 85 | C8: =B9-B8 -> 30
A9: 6 | B9: =ROUND(IF(A9<=参数说明!$A$14,FORECAST(A9,参数说明!$B$13:$B$14,参数说明!$A$13:$A$14),IF(A9<=参数说明!$A$15,FORECAST(A9,参数说明!$B$14:$B$15,参数说明!$A$14:$A$15),IF(A9<=参数说明!$A$16,FORECAST(A9,参数说明!$B$15:$B$16,参数说明!$A$15:$A$16),IF(A9<=参数说明!$A$17,FORECAST(A9,参数说明!$B$16:$B$17,参数说明!$A$16:$A$17),IF(A9<=参数说明!$A$18,FORECAST(A9,参数说明!$B$17:$B$18,参数说明!$A$17:$A$18),IF(A9<=参数说明!$A$19,FORECAST(A9,参数说明!$B$18:$B$19,参数说明!$A$18:$A$19),FORECAST(A9,参数说明!$B$19:$B$20,参数说明!$A$19:$A$20)))))))/5,0)*5 -> 115 | C9: =B10-B9 -> 25
A10: 7 | B10: =ROUND(IF(A10<=参数说明!$A$14,FORECAST(A10,参数说明!$B$13:$B$14,参数说明!$A$13:$A$14),IF(A10<=参数说明!$A$15,FORECAST(A10,参数说明!$B$14:$B$15,参数说明!$A$14:$A$15),IF(A10<=参数说明!$A$16,FORECAST(A10,参数说明!$B$15:$B$16,参数说明!$A$15:$A$16),IF(A10<=参数说明!$A$17,FORECAST(A10,参数说明!$B$16:$B$17,参数说明!$A$16:$A$17),IF(A10<=参数说明!$A$18,FORECAST(A10,参数说明!$B$17:$B$18,参数说明!$A$17:$A$18),IF(A10<=参数说明!$A$19,FORECAST(A10,参数说明!$B$18:$B$19,参数说明!$A$18:$A$19),FORECAST(A10,参数说明!$B$19:$B$20,参数说明!$A$19:$A$20)))))))/5,0)*5 -> 140 | C10: =B11-B10 -> 30
A11: 8 | B11: =ROUND(IF(A11<=参数说明!$A$14,FORECAST(A11,参数说明!$B$13:$B$14,参数说明!$A$13:$A$14),IF(A11<=参数说明!$A$15,FORECAST(A11,参数说明!$B$14:$B$15,参数说明!$A$14:$A$15),IF(A11<=参数说明!$A$16,FORECAST(A11,参数说明!$B$15:$B$16,参数说明!$A$15:$A$16),IF(A11<=参数说明!$A$17,FORECAST(A11,参数说明!$B$16:$B$17,参数说明!$A$16:$A$17),IF(A11<=参数说明!$A$18,FORECAST(A11,参数说明!$B$17:$B$18,参数说明!$A$17:$A$18),IF(A11<=参数说明!$A$19,FORECAST(A11,参数说明!$B$18:$B$19,参数说明!$A$18:$A$19),FORECAST(A11,参数说明!$B$19:$B$20,参数说明!$A$19:$A$20)))))))/5,0)*5 -> 170 | C11: =B12-B11 -> 25
A12: 9 | B12: =ROUND(IF(A12<=参数说明!$A$14,FORECAST(A12,参数说明!$B$13:$B$14,参数说明!$A$13:$A$14),IF(A12<=参数说明!$A$15,FORECAST(A12,参数说明!$B$14:$B$15,参数说明!$A$14:$A$15),IF(A12<=参数说明!$A$16,FORECAST(A12,参数说明!$B$15:$B$16,参数说明!$A$15:$A$16),IF(A12<=参数说明!$A$17,FORECAST(A12,参数说明!$B$16:$B$17,参数说明!$A$16:$A$17),IF(A12<=参数说明!$A$18,FORECAST(A12,参数说明!$B$17:$B$18,参数说明!$A$17:$A$18),IF(A12<=参数说明!$A$19,FORECAST(A12,参数说明!$B$18:$B$19,参数说明!$A$18:$A$19),FORECAST(A12,参数说明!$B$19:$B$20,参数说明!$A$19:$A$20)))))))/5,0)*5 -> 195 | C12: =B13-B12 -> 30
A13: 10 | B13: =ROUND(IF(A13<=参数说明!$A$14,FORECAST(A13,参数说明!$B$13:$B$14,参数说明!$A$13:$A$14),IF(A13<=参数说明!$A$15,FORECAST(A13,参数说明!$B$14:$B$15,参数说明!$A$14:$A$15),IF(A13<=参数说明!$A$16,FORECAST(A13,参数说明!$B$15:$B$16,参数说明!$A$15:$A$16),IF(A13<=参数说明!$A$17,FORECAST(A13,参数说明!$B$16:$B$17,参数说明!$A$16:$A$17),IF(A13<=参数说明!$A$18,FORECAST(A13,参数说明!$B$17:$B$18,参数说明!$A$17:$A$18),IF(A13<=参数说明!$A$19,FORECAST(A13,参数说明!$B$18:$B$19,参数说明!$A$18:$A$19),FORECAST(A13,参数说明!$B$19:$B$20,参数说明!$A$19:$A$20)))))))/5,0)*5 -> 225 | C13: =B14-B13 -> 60
A14: 11 | B14: =ROUND(IF(A14<=参数说明!$A$14,FORECAST(A14,参数说明!$B$13:$B$14,参数说明!$A$13:$A$14),IF(A14<=参数说明!$A$15,FORECAST(A14,参数说明!$B$14:$B$15,参数说明!$A$14:$A$15),IF(A14<=参数说明!$A$16,FORECAST(A14,参数说明!$B$15:$B$16,参数说明!$A$15:$A$16),IF(A14<=参数说明!$A$17,FORECAST(A14,参数说明!$B$16:$B$17,参数说明!$A$16:$A$17),IF(A14<=参数说明!$A$18,FORECAST(A14,参数说明!$B$17:$B$18,参数说明!$A$17:$A$18),IF(A14<=参数说明!$A$19,FORECAST(A14,参数说明!$B$18:$B$19,参数说明!$A$18:$A$19),FORECAST(A14,参数说明!$B$19:$B$20,参数说明!$A$19:$A$20)))))))/5,0)*5 -> 285 | C14: =B15-B14 -> 65
A15: 12 | B15: =ROUND(IF(A15<=参数说明!$A$14,FORECAST(A15,参数说明!$B$13:$B$14,参数说明!$A$13:$A$14),IF(A15<=参数说明!$A$15,FORECAST(A15,参数说明!$B$14:$B$15,参数说明!$A$14:$A$15),IF(A15<=参数说明!$A$16,FORECAST(A15,参数说明!$B$15:$B$16,参数说明!$A$15:$A$16),IF(A15<=参数说明!$A$17,FORECAST(A15,参数说明!$B$16:$B$17,参数说明!$A$16:$A$17),IF(A15<=参数说明!$A$18,FORECAST(A15,参数说明!$B$17:$B$18,参数说明!$A$17:$A$18),IF(A15<=参数说明!$A$19,FORECAST(A15,参数说明!$B$18:$B$19,参数说明!$A$18:$A$19),FORECAST(A15,参数说明!$B$19:$B$20,参数说明!$A$19:$A$20)))))))/5,0)*5 -> 350 | C15: =B16-B15 -> 60
... A102: 99 | B102: =ROUND(IF(A102<=参数说明!$A$14,FORECAST(A102,参数说明!$B$13:$B$14,参数说明!$A$13:$A$14),IF(A102<=参数说明!$A$15,FORECAST(A102,参数说明!$B$14:$B$15,参数说明!$A$14:$A$15),IF(A102<=参数说明!$A$16,FORECAST(A102,参数说明!$B$15:$B$16,参数说明!$A$15:$A$16),IF(A102<=参数说明!$A$17,FORECAST(A102,参数说明!$B$16:$B$17,参数说明!$A$16:$A$17),IF(A102<=参数说明!$A$18,FORECAST(A102,参数说明!$B$17:$B$18,参数说明!$A$17:$A$18),IF(A102<=参数说明!$A$19,FORECAST(A102,参数说明!$B$18:$B$19,参数说明!$A$18:$A$19),FORECAST(A102,参数说明!$B$19:$B$20,参数说明!$A$19:$A$20)))))))/5,0)*5 -> 27125 | C102: =B103-B102 -> 475
A103: 100 | B103: =ROUND(IF(A103<=参数说明!$A$14,FORECAST(A103,参数说明!$B$13:$B$14,参数说明!$A$13:$A$14),IF(A103<=参数说明!$A$15,FORECAST(A103,参数说明!$B$14:$B$15,参数说明!$A$14:$A$15),IF(A103<=参数说明!$A$16,FORECAST(A103,参数说明!$B$15:$B$16,参数说明!$A$15:$A$16),IF(A103<=参数说明!$A$17,FORECAST(A103,参数说明!$B$16:$B$17,参数说明!$A$16:$A$17),IF(A103<=参数说明!$A$18,FORECAST(A103,参数说明!$B$17:$B$18,参数说明!$A$17:$A$18),IF(A103<=参数说明!$A$19,FORECAST(A103,参数说明!$B$18:$B$19,参数说明!$A$18:$A$19),FORECAST(A103,参数说明!$B$19:$B$20,参数说明!$A$19:$A$20)))))))/5,0)*5 -> 27600 | C103: ="Max" -> Max

Sheet 日期-等级经验曲线
A1: 日期-等级经验曲线
A3: 新增日期 | B3: 相对天数 | C3: 当日 XP | D3: 累计经验 | E3: 等级 | F3: 关键节点 | G3: 关键节点表
A4: =参数说明!$B$8+0 -> 46197 | B4: 0 | C4: =IF(B4=0,0,IF(B4<=7,FORECAST(B4,参数说明!$B$24:$B$25,参数说明!$A$24:$A$25),IF(B4<=30,FORECAST(B4,参数说明!$B$25:$B$26,参数说明!$A$25:$A$26),IF(B4<=60,FORECAST(B4,参数说明!$B$26:$B$27,参数说明!$A$26:$A$27),IF(B4<=90,FORECAST(B4,参数说明!$B$27:$B$28,参数说明!$A$27:$A$28),IF(B4<=180,FORECAST(B4,参数说明!$B$28:$B$29,参数说明!$A$28:$A$29),FORECAST(B4,参数说明!$B$29:$B$30,参数说明!$A$29:$A$30))))))) -> 0 | D4: =C4 -> 0 | E4: =IF(D4<'等级-经验对照'!$B$4,0,LOOKUP(D4,'等级-经验对照'!$B$4:$B$103,'等级-经验对照'!$A$4:$A$103)) -> 0 | F4: =IF(OR(B4=1,B4=7,B4=30,B4=60,B4=90,B4=180,B4=365),"D"&B4&" / Lv"&E4&" / "&ROUND(D4,0)&" XP","") | G4: 节点 | H4: 日期 | I4: 当日 XP | J4: 累计经验 | K4: 等级/说明
A5: =参数说明!$B$8+1 -> 46198 | B5: 1 | C5: =IF(B5=0,0,IF(B5<=7,FORECAST(B5,参数说明!$B$24:$B$25,参数说明!$A$24:$A$25),IF(B5<=30,FORECAST(B5,参数说明!$B$25:$B$26,参数说明!$A$25:$A$26),IF(B5<=60,FORECAST(B5,参数说明!$B$26:$B$27,参数说明!$A$26:$A$27),IF(B5<=90,FORECAST(B5,参数说明!$B$27:$B$28,参数说明!$A$27:$A$28),IF(B5<=180,FORECAST(B5,参数说明!$B$28:$B$29,参数说明!$A$28:$A$29),FORECAST(B5,参数说明!$B$29:$B$30,参数说明!$A$29:$A$30))))))) -> 30 | D5: =D4+C5 -> 30 | E5: =IF(D5<'等级-经验对照'!$B$4,0,LOOKUP(D5,'等级-经验对照'!$B$4:$B$103,'等级-经验对照'!$A$4:$A$103)) -> 3 | F5: =IF(OR(B5=1,B5=7,B5=30,B5=60,B5=90,B5=180,B5=365),"D"&B5&" / Lv"&E5&" / "&ROUND(D5,0)&" XP","") -> D1 / Lv3 / 30 XP | G5: D1 | H5: =_xlfn.XLOOKUP(1,$B$4:$B$369,$A$4:$A$369) -> 46198 | I5: =_xlfn.XLOOKUP(1,$B$4:$B$369,$C$4:$C$369) -> 30 | J5: =_xlfn.XLOOKUP(1,$B$4:$B$369,$D$4:$D$369) -> 30 | K5: ="Lv"&_xlfn.XLOOKUP(1,$B$4:$B$369,$E$4:$E$369)&" / "&_xlfn.XLOOKUP(1,$B$4:$B$369,$F$4:$F$369) -> Lv3 / D1 / Lv3 / 30 XP
A6: =参数说明!$B$8+2 -> 46199 | B6: 2 | C6: =IF(B6=0,0,IF(B6<=7,FORECAST(B6,参数说明!$B$24:$B$25,参数说明!$A$24:$A$25),IF(B6<=30,FORECAST(B6,参数说明!$B$25:$B$26,参数说明!$A$25:$A$26),IF(B6<=60,FORECAST(B6,参数说明!$B$26:$B$27,参数说明!$A$26:$A$27),IF(B6<=90,FORECAST(B6,参数说明!$B$27:$B$28,参数说明!$A$27:$A$28),IF(B6<=180,FORECAST(B6,参数说明!$B$28:$B$29,参数说明!$A$28:$A$29),FORECAST(B6,参数说明!$B$29:$B$30,参数说明!$A$29:$A$30))))))) -> 30.833333 | D6: =D5+C6 -> 60.833333 | E6: =IF(D6<'等级-经验对照'!$B$4,0,LOOKUP(D6,'等级-经验对照'!$B$4:$B$103,'等级-经验对照'!$A$4:$A$103)) -> 4 | F6: =IF(OR(B6=1,B6=7,B6=30,B6=60,B6=90,B6=180,B6=365),"D"&B6&" / Lv"&E6&" / "&ROUND(D6,0)&" XP","") | G6: D7 | H6: =_xlfn.XLOOKUP(7,$B$4:$B$369,$A$4:$A$369) -> 46204 | I6: =_xlfn.XLOOKUP(7,$B$4:$B$369,$C$4:$C$369) -> 35 | J6: =_xlfn.XLOOKUP(7,$B$4:$B$369,$D$4:$D$369) -> 227.5 | K6: ="Lv"&_xlfn.XLOOKUP(7,$B$4:$B$369,$E$4:$E$369)&" / "&_xlfn.XLOOKUP(7,$B$4:$B$369,$F$4:$F$369) -> Lv10 / D7 / Lv10 / 228 XP
A7: =参数说明!$B$8+3 -> 46200 | B7: 3 | C7: =IF(B7=0,0,IF(B7<=7,FORECAST(B7,参数说明!$B$24:$B$25,参数说明!$A$24:$A$25),IF(B7<=30,FORECAST(B7,参数说明!$B$25:$B$26,参数说明!$A$25:$A$26),IF(B7<=60,FORECAST(B7,参数说明!$B$26:$B$27,参数说明!$A$26:$A$27),IF(B7<=90,FORECAST(B7,参数说明!$B$27:$B$28,参数说明!$A$27:$A$28),IF(B7<=180,FORECAST(B7,参数说明!$B$28:$B$29,参数说明!$A$28:$A$29),FORECAST(B7,参数说明!$B$29:$B$30,参数说明!$A$29:$A$30))))))) -> 31.666667 | D7: =D6+C7 -> 92.5 | E7: =IF(D7<'等级-经验对照'!$B$4,0,LOOKUP(D7,'等级-经验对照'!$B$4:$B$103,'等级-经验对照'!$A$4:$A$103)) -> 5 | F7: =IF(OR(B7=1,B7=7,B7=30,B7=60,B7=90,B7=180,B7=365),"D"&B7&" / Lv"&E7&" / "&ROUND(D7,0)&" XP","") | G7: D30 | H7: =_xlfn.XLOOKUP(30,$B$4:$B$369,$A$4:$A$369) -> 46227 | I7: =_xlfn.XLOOKUP(30,$B$4:$B$369,$C$4:$C$369) -> 45 | J7: =_xlfn.XLOOKUP(30,$B$4:$B$369,$D$4:$D$369) -> 1152.5 | K7: ="Lv"&_xlfn.XLOOKUP(30,$B$4:$B$369,$E$4:$E$369)&" / "&_xlfn.XLOOKUP(30,$B$4:$B$369,$F$4:$F$369) -> Lv25 / D30 / Lv25 / 1153 XP
A8: =参数说明!$B$8+4 -> 46201 | B8: 4 | C8: =IF(B8=0,0,IF(B8<=7,FORECAST(B8,参数说明!$B$24:$B$25,参数说明!$A$24:$A$25),IF(B8<=30,FORECAST(B8,参数说明!$B$25:$B$26,参数说明!$A$25:$A$26),IF(B8<=60,FORECAST(B8,参数说明!$B$26:$B$27,参数说明!$A$26:$A$27),IF(B8<=90,FORECAST(B8,参数说明!$B$27:$B$28,参数说明!$A$27:$A$28),IF(B8<=180,FORECAST(B8,参数说明!$B$28:$B$29,参数说明!$A$28:$A$29),FORECAST(B8,参数说明!$B$29:$B$30,参数说明!$A$29:$A$30))))))) -> 32.5 | D8: =D7+C8 -> 125 | E8: =IF(D8<'等级-经验对照'!$B$4,0,LOOKUP(D8,'等级-经验对照'!$B$4:$B$103,'等级-经验对照'!$A$4:$A$103)) -> 6 | F8: =IF(OR(B8=1,B8=7,B8=30,B8=60,B8=90,B8=180,B8=365),"D"&B8&" / Lv"&E8&" / "&ROUND(D8,0)&" XP","") | G8: D60 | H8: =_xlfn.XLOOKUP(60,$B$4:$B$369,$A$4:$A$369) -> 46257 | I8: =_xlfn.XLOOKUP(60,$B$4:$B$369,$C$4:$C$369) -> 55 | J8: =_xlfn.XLOOKUP(60,$B$4:$B$369,$D$4:$D$369) -> 2657.5 | K8: ="Lv"&_xlfn.XLOOKUP(60,$B$4:$B$369,$E$4:$E$369)&" / "&_xlfn.XLOOKUP(60,$B$4:$B$369,$F$4:$F$369) -> Lv37 / D60 / Lv37 / 2658 XP
A9: =参数说明!$B$8+5 -> 46202 | B9: 5 | C9: =IF(B9=0,0,IF(B9<=7,FORECAST(B9,参数说明!$B$24:$B$25,参数说明!$A$24:$A$25),IF(B9<=30,FORECAST(B9,参数说明!$B$25:$B$26,参数说明!$A$25:$A$26),IF(B9<=60,FORECAST(B9,参数说明!$B$26:$B$27,参数说明!$A$26:$A$27),IF(B9<=90,FORECAST(B9,参数说明!$B$27:$B$28,参数说明!$A$27:$A$28),IF(B9<=180,FORECAST(B9,参数说明!$B$28:$B$29,参数说明!$A$28:$A$29),FORECAST(B9,参数说明!$B$29:$B$30,参数说明!$A$29:$A$30))))))) -> 33.333333 | D9: =D8+C9 -> 158.33333 | E9: =IF(D9<'等级-经验对照'!$B$4,0,LOOKUP(D9,'等级-经验对照'!$B$4:$B$103,'等级-经验对照'!$A$4:$A$103)) -> 7 | F9: =IF(OR(B9=1,B9=7,B9=30,B9=60,B9=90,B9=180,B9=365),"D"&B9&" / Lv"&E9&" / "&ROUND(D9,0)&" XP","") | G9: D90 | H9: =_xlfn.XLOOKUP(90,$B$4:$B$369,$A$4:$A$369) -> 46287 | I9: =_xlfn.XLOOKUP(90,$B$4:$B$369,$C$4:$C$369) -> 65 | J9: =_xlfn.XLOOKUP(90,$B$4:$B$369,$D$4:$D$369) -> 4462.5 | K9: ="Lv"&_xlfn.XLOOKUP(90,$B$4:$B$369,$E$4:$E$369)&" / "&_xlfn.XLOOKUP(90,$B$4:$B$369,$F$4:$F$369) -> Lv45 / D90 / Lv45 / 4463 XP
A10: =参数说明!$B$8+6 -> 46203 | B10: 6 | C10: =IF(B10=0,0,IF(B10<=7,FORECAST(B10,参数说明!$B$24:$B$25,参数说明!$A$24:$A$25),IF(B10<=30,FORECAST(B10,参数说明!$B$25:$B$26,参数说明!$A$25:$A$26),IF(B10<=60,FORECAST(B10,参数说明!$B$26:$B$27,参数说明!$A$26:$A$27),IF(B10<=90,FORECAST(B10,参数说明!$B$27:$B$28,参数说明!$A$27:$A$28),IF(B10<=180,FORECAST(B10,参数说明!$B$28:$B$29,参数说明!$A$28:$A$29),FORECAST(B10,参数说明!$B$29:$B$30,参数说明!$A$29:$A$30))))))) -> 34.166667 | D10: =D9+C10 -> 192.5 | E10: =IF(D10<'等级-经验对照'!$B$4,0,LOOKUP(D10,'等级-经验对照'!$B$4:$B$103,'等级-经验对照'!$A$4:$A$103)) -> 8 | F10: =IF(OR(B10=1,B10=7,B10=30,B10=60,B10=90,B10=180,B10=365),"D"&B10&" / Lv"&E10&" / "&ROUND(D10,0)&" XP","") | G10: D180 | H10: =_xlfn.XLOOKUP(180,$B$4:$B$369,$A$4:$A$369) -> 46377 | I10: =_xlfn.XLOOKUP(180,$B$4:$B$369,$C$4:$C$369) -> 80 | J10: =_xlfn.XLOOKUP(180,$B$4:$B$369,$D$4:$D$369) -> 10995 | K10: ="Lv"&_xlfn.XLOOKUP(180,$B$4:$B$369,$E$4:$E$369)&" / "&_xlfn.XLOOKUP(180,$B$4:$B$369,$F$4:$F$369) -> Lv65 / D180 / Lv65 / 10995 XP
A11: =参数说明!$B$8+7 -> 46204 | B11: 7 | C11: =IF(B11=0,0,IF(B11<=7,FORECAST(B11,参数说明!$B$24:$B$25,参数说明!$A$24:$A$25),IF(B11<=30,FORECAST(B11,参数说明!$B$25:$B$26,参数说明!$A$25:$A$26),IF(B11<=60,FORECAST(B11,参数说明!$B$26:$B$27,参数说明!$A$26:$A$27),IF(B11<=90,FORECAST(B11,参数说明!$B$27:$B$28,参数说明!$A$27:$A$28),IF(B11<=180,FORECAST(B11,参数说明!$B$28:$B$29,参数说明!$A$28:$A$29),FORECAST(B11,参数说明!$B$29:$B$30,参数说明!$A$29:$A$30))))))) -> 35 | D11: =D10+C11 -> 227.5 | E11: =IF(D11<'等级-经验对照'!$B$4,0,LOOKUP(D11,'等级-经验对照'!$B$4:$B$103,'等级-经验对照'!$A$4:$A$103)) -> 10 | F11: =IF(OR(B11=1,B11=7,B11=30,B11=60,B11=90,B11=180,B11=365),"D"&B11&" / Lv"&E11&" / "&ROUND(D11,0)&" XP","") -> D7 / Lv10 / 228 XP | G11: D365 | H11: =_xlfn.XLOOKUP(365,$B$4:$B$369,$A$4:$A$369) -> 46562 | I11: =_xlfn.XLOOKUP(365,$B$4:$B$369,$C$4:$C$369) -> 100 | J11: =_xlfn.XLOOKUP(365,$B$4:$B$369,$D$4:$D$369) -> 27655 | K11: ="Lv"&_xlfn.XLOOKUP(365,$B$4:$B$369,$E$4:$E$369)&" / "&_xlfn.XLOOKUP(365,$B$4:$B$369,$F$4:$F$369) -> Lv100 / D365 / Lv100 / 27655 XP
A12: =参数说明!$B$8+8 -> 46205 | B12: 8 | C12: =IF(B12=0,0,IF(B12<=7,FORECAST(B12,参数说明!$B$24:$B$25,参数说明!$A$24:$A$25),IF(B12<=30,FORECAST(B12,参数说明!$B$25:$B$26,参数说明!$A$25:$A$26),IF(B12<=60,FORECAST(B12,参数说明!$B$26:$B$27,参数说明!$A$26:$A$27),IF(B12<=90,FORECAST(B12,参数说明!$B$27:$B$28,参数说明!$A$27:$A$28),IF(B12<=180,FORECAST(B12,参数说明!$B$28:$B$29,参数说明!$A$28:$A$29),FORECAST(B12,参数说明!$B$29:$B$30,参数说明!$A$29:$A$30))))))) -> 35.434783 | D12: =D11+C12 -> 262.93478 | E12: =IF(D12<'等级-经验对照'!$B$4,0,LOOKUP(D12,'等级-经验对照'!$B$4:$B$103,'等级-经验对照'!$A$4:$A$103)) -> 10 | F12: =IF(OR(B12=1,B12=7,B12=30,B12=60,B12=90,B12=180,B12=365),"D"&B12&" / Lv"&E12&" / "&ROUND(D12,0)&" XP","") | G12: 图表说明 | H12: X 轴使用相对天数 D0-D365，比日期更清楚。
A13: =参数说明!$B$8+9 -> 46206 | B13: 9 | C13: =IF(B13=0,0,IF(B13<=7,FORECAST(B13,参数说明!$B$24:$B$25,参数说明!$A$24:$A$25),IF(B13<=30,FORECAST(B13,参数说明!$B$25:$B$26,参数说明!$A$25:$A$26),IF(B13<=60,FORECAST(B13,参数说明!$B$26:$B$27,参数说明!$A$26:$A$27),IF(B13<=90,FORECAST(B13,参数说明!$B$27:$B$28,参数说明!$A$27:$A$28),IF(B13<=180,FORECAST(B13,参数说明!$B$28:$B$29,参数说明!$A$28:$A$29),FORECAST(B13,参数说明!$B$29:$B$30,参数说明!$A$29:$A$30))))))) -> 35.869565 | D13: =D12+C13 -> 298.80435 | E13: =IF(D13<'等级-经验对照'!$B$4,0,LOOKUP(D13,'等级-经验对照'!$B$4:$B$103,'等级-经验对照'!$A$4:$A$103)) -> 11 | F13: =IF(OR(B13=1,B13=7,B13=30,B13=60,B13=90,B13=180,B13=365),"D"&B13&" / Lv"&E13&" / "&ROUND(D13,0)&" XP","") | G13: 数据源 | H13: 等级线：B/E；累计经验线：B/D；当日 XP 辅助线：B/C。
A14: =参数说明!$B$8+10 -> 46207 | B14: 10 | C14: =IF(B14=0,0,IF(B14<=7,FORECAST(B14,参数说明!$B$24:$B$25,参数说明!$A$24:$A$25),IF(B14<=30,FORECAST(B14,参数说明!$B$25:$B$26,参数说明!$A$25:$A$26),IF(B14<=60,FORECAST(B14,参数说明!$B$26:$B$27,参数说明!$A$26:$A$27),IF(B14<=90,FORECAST(B14,参数说明!$B$27:$B$28,参数说明!$A$27:$A$28),IF(B14<=180,FORECAST(B14,参数说明!$B$28:$B$29,参数说明!$A$28:$A$29),FORECAST(B14,参数说明!$B$29:$B$30,参数说明!$A$29:$A$30))))))) -> 36.304348 | D14: =D13+C14 -> 335.1087 | E14: =IF(D14<'等级-经验对照'!$B$4,0,LOOKUP(D14,'等级-经验对照'!$B$4:$B$103,'等级-经验对照'!$A$4:$A$103)) -> 11 | F14: =IF(OR(B14=1,B14=7,B14=30,B14=60,B14=90,B14=180,B14=365),"D"&B14&" / Lv"&E14&" / "&ROUND(D14,0)&" XP","")
A15: =参数说明!$B$8+11 -> 46208 | B15: 11 | C15: =IF(B15=0,0,IF(B15<=7,FORECAST(B15,参数说明!$B$24:$B$25,参数说明!$A$24:$A$25),IF(B15<=30,FORECAST(B15,参数说明!$B$25:$B$26,参数说明!$A$25:$A$26),IF(B15<=60,FORECAST(B15,参数说明!$B$26:$B$27,参数说明!$A$26:$A$27),IF(B15<=90,FORECAST(B15,参数说明!$B$27:$B$28,参数说明!$A$27:$A$28),IF(B15<=180,FORECAST(B15,参数说明!$B$28:$B$29,参数说明!$A$28:$A$29),FORECAST(B15,参数说明!$B$29:$B$30,参数说明!$A$29:$A$30))))))) -> 36.73913 | D15: =D14+C15 -> 371.84783 | E15: =IF(D15<'等级-经验对照'!$B$4,0,LOOKUP(D15,'等级-经验对照'!$B$4:$B$103,'等级-经验对照'!$A$4:$A$103)) -> 12 | F15: =IF(OR(B15=1,B15=7,B15=30,B15=60,B15=90,B15=180,B15=365),"D"&B15&" / Lv"&E15&" / "&ROUND(D15,0)&" XP","")
A16: =参数说明!$B$8+12 -> 46209 | B16: 12 | C16: =IF(B16=0,0,IF(B16<=7,FORECAST(B16,参数说明!$B$24:$B$25,参数说明!$A$24:$A$25),IF(B16<=30,FORECAST(B16,参数说明!$B$25:$B$26,参数说明!$A$25:$A$26),IF(B16<=60,FORECAST(B16,参数说明!$B$26:$B$27,参数说明!$A$26:$A$27),IF(B16<=90,FORECAST(B16,参数说明!$B$27:$B$28,参数说明!$A$27:$A$28),IF(B16<=180,FORECAST(B16,参数说明!$B$28:$B$29,参数说明!$A$28:$A$29),FORECAST(B16,参数说明!$B$29:$B$30,参数说明!$A$29:$A$30))))))) -> 37.173913 | D16: =D15+C16 -> 409.02174 | E16: =IF(D16<'等级-经验对照'!$B$4,0,LOOKUP(D16,'等级-经验对照'!$B$4:$B$103,'等级-经验对照'!$A$4:$A$103)) -> 12 | F16: =IF(OR(B16=1,B16=7,B16=30,B16=60,B16=90,B16=180,B16=365),"D"&B16&" / Lv"&E16&" / "&ROUND(D16,0)&" XP","")
A17: =参数说明!$B$8+13 -> 46210 | B17: 13 | C17: =IF(B17=0,0,IF(B17<=7,FORECAST(B17,参数说明!$B$24:$B$25,参数说明!$A$24:$A$25),IF(B17<=30,FORECAST(B17,参数说明!$B$25:$B$26,参数说明!$A$25:$A$26),IF(B17<=60,FORECAST(B17,参数说明!$B$26:$B$27,参数说明!$A$26:$A$27),IF(B17<=90,FORECAST(B17,参数说明!$B$27:$B$28,参数说明!$A$27:$A$28),IF(B17<=180,FORECAST(B17,参数说明!$B$28:$B$29,参数说明!$A$28:$A$29),FORECAST(B17,参数说明!$B$29:$B$30,参数说明!$A$29:$A$30))))))) -> 37.608696 | D17: =D16+C17 -> 446.63043 | E17: =IF(D17<'等级-经验对照'!$B$4,0,LOOKUP(D17,'等级-经验对照'!$B$4:$B$103,'等级-经验对照'!$A$4:$A$103)) -> 13 | F17: =IF(OR(B17=1,B17=7,B17=30,B17=60,B17=90,B17=180,B17=365),"D"&B17&" / Lv"&E17&" / "&ROUND(D17,0)&" XP","")
A18: =参数说明!$B$8+14 -> 46211 | B18: 14 | C18: =IF(B18=0,0,IF(B18<=7,FORECAST(B18,参数说明!$B$24:$B$25,参数说明!$A$24:$A$25),IF(B18<=30,FORECAST(B18,参数说明!$B$25:$B$26,参数说明!$A$25:$A$26),IF(B18<=60,FORECAST(B18,参数说明!$B$26:$B$27,参数说明!$A$26:$A$27),IF(B18<=90,FORECAST(B18,参数说明!$B$27:$B$28,参数说明!$A$27:$A$28),IF(B18<=180,FORECAST(B18,参数说明!$B$28:$B$29,参数说明!$A$28:$A$29),FORECAST(B18,参数说明!$B$29:$B$30,参数说明!$A$29:$A$30))))))) -> 38.043478 | D18: =D17+C18 -> 484.67391 | E18: =IF(D18<'等级-经验对照'!$B$4,0,LOOKUP(D18,'等级-经验对照'!$B$4:$B$103,'等级-经验对照'!$A$4:$A$103)) -> 14 | F18: =IF(OR(B18=1,B18=7,B18=30,B18=60,B18=90,B18=180,B18=365),"D"&B18&" / Lv"&E18&" / "&ROUND(D18,0)&" XP","")
A19: =参数说明!$B$8+15 -> 46212 | B19: 15 | C19: =IF(B19=0,0,IF(B19<=7,FORECAST(B19,参数说明!$B$24:$B$25,参数说明!$A$24:$A$25),IF(B19<=30,FORECAST(B19,参数说明!$B$25:$B$26,参数说明!$A$25:$A$26),IF(B19<=60,FORECAST(B19,参数说明!$B$26:$B$27,参数说明!$A$26:$A$27),IF(B19<=90,FORECAST(B19,参数说明!$B$27:$B$28,参数说明!$A$27:$A$28),IF(B19<=180,FORECAST(B19,参数说明!$B$28:$B$29,参数说明!$A$28:$A$29),FORECAST(B19,参数说明!$B$29:$B$30,参数说明!$A$29:$A$30))))))) -> 38.478261 | D19: =D18+C19 -> 523.15217 | E19: =IF(D19<'等级-经验对照'!$B$4,0,LOOKUP(D19,'等级-经验对照'!$B$4:$B$103,'等级-经验对照'!$A$4:$A$103)) -> 14 | F19: =IF(OR(B19=1,B19=7,B19=30,B19=60,B19=90,B19=180,B19=365),"D"&B19&" / Lv"&E19&" / "&ROUND(D19,0)&" XP","")
A20: =参数说明!$B$8+16 -> 46213 | B20: 16 | C20: =IF(B20=0,0,IF(B20<=7,FORECAST(B20,参数说明!$B$24:$B$25,参数说明!$A$24:$A$25),IF(B20<=30,FORECAST(B20,参数说明!$B$25:$B$26,参数说明!$A$25:$A$26),IF(B20<=60,FORECAST(B20,参数说明!$B$26:$B$27,参数说明!$A$26:$A$27),IF(B20<=90,FORECAST(B20,参数说明!$B$27:$B$28,参数说明!$A$27:$A$28),IF(B20<=180,FORECAST(B20,参数说明!$B$28:$B$29,参数说明!$A$28:$A$29),FORECAST(B20,参数说明!$B$29:$B$30,参数说明!$A$29:$A$30))))))) -> 38.913043 | D20: =D19+C20 -> 562.06522 | E20: =IF(D20<'等级-经验对照'!$B$4,0,LOOKUP(D20,'等级-经验对照'!$B$4:$B$103,'等级-经验对照'!$A$4:$A$103)) -> 15 | F20: =IF(OR(B20=1,B20=7,B20=30,B20=60,B20=90,B20=180,B20=365),"D"&B20&" / Lv"&E20&" / "&ROUND(D20,0)&" XP","")
A21: =参数说明!$B$8+17 -> 46214 | B21: 17 | C21: =IF(B21=0,0,IF(B21<=7,FORECAST(B21,参数说明!$B$24:$B$25,参数说明!$A$24:$A$25),IF(B21<=30,FORECAST(B21,参数说明!$B$25:$B$26,参数说明!$A$25:$A$26),IF(B21<=60,FORECAST(B21,参数说明!$B$26:$B$27,参数说明!$A$26:$A$27),IF(B21<=90,FORECAST(B21,参数说明!$B$27:$B$28,参数说明!$A$27:$A$28),IF(B21<=180,FORECAST(B21,参数说明!$B$28:$B$29,参数说明!$A$28:$A$29),FORECAST(B21,参数说明!$B$29:$B$30,参数说明!$A$29:$A$30))))))) -> 39.347826 | D21: =D20+C21 -> 601.41304 | E21: =IF(D21<'等级-经验对照'!$B$4,0,LOOKUP(D21,'等级-经验对照'!$B$4:$B$103,'等级-经验对照'!$A$4:$A$103)) -> 16 | F21: =IF(OR(B21=1,B21=7,B21=30,B21=60,B21=90,B21=180,B21=365),"D"&B21&" / Lv"&E21&" / "&ROUND(D21,0)&" XP","")
A22: =参数说明!$B$8+18 -> 46215 | B22: 18 | C22: =IF(B22=0,0,IF(B22<=7,FORECAST(B22,参数说明!$B$24:$B$25,参数说明!$A$24:$A$25),IF(B22<=30,FORECAST(B22,参数说明!$B$25:$B$26,参数说明!$A$25:$A$26),IF(B22<=60,FORECAST(B22,参数说明!$B$26:$B$27,参数说明!$A$26:$A$27),IF(B22<=90,FORECAST(B22,参数说明!$B$27:$B$28,参数说明!$A$27:$A$28),IF(B22<=180,FORECAST(B22,参数说明!$B$28:$B$29,参数说明!$A$28:$A$29),FORECAST(B22,参数说明!$B$29:$B$30,参数说明!$A$29:$A$30))))))) -> 39.782609 | D22: =D21+C22 -> 641.19565 | E22: =IF(D22<'等级-经验对照'!$B$4,0,LOOKUP(D22,'等级-经验对照'!$B$4:$B$103,'等级-经验对照'!$A$4:$A$103)) -> 16 | F22: =IF(OR(B22=1,B22=7,B22=30,B22=60,B22=90,B22=180,B22=365),"D"&B22&" / Lv"&E22&" / "&ROUND(D22,0)&" XP","")
A23: =参数说明!$B$8+19 -> 46216 | B23: 19 | C23: =IF(B23=0,0,IF(B23<=7,FORECAST(B23,参数说明!$B$24:$B$25,参数说明!$A$24:$A$25),IF(B23<=30,FORECAST(B23,参数说明!$B$25:$B$26,参数说明!$A$25:$A$26),IF(B23<=60,FORECAST(B23,参数说明!$B$26:$B$27,参数说明!$A$26:$A$27),IF(B23<=90,FORECAST(B23,参数说明!$B$27:$B$28,参数说明!$A$27:$A$28),IF(B23<=180,FORECAST(B23,参数说明!$B$28:$B$29,参数说明!$A$28:$A$29),FORECAST(B23,参数说明!$B$29:$B$30,参数说明!$A$29:$A$30))))))) -> 40.217391 | D23: =D22+C23 -> 681.41304 | E23: =IF(D23<'等级-经验对照'!$B$4,0,LOOKUP(D23,'等级-经验对照'!$B$4:$B$103,'等级-经验对照'!$A$4:$A$103)) -> 17 | F23: =IF(OR(B23=1,B23=7,B23=30,B23=60,B23=90,B23=180,B23=365),"D"&B23&" / Lv"&E23&" / "&ROUND(D23,0)&" XP","")
A24: =参数说明!$B$8+20 -> 46217 | B24: 20 | C24: =IF(B24=0,0,IF(B24<=7,FORECAST(B24,参数说明!$B$24:$B$25,参数说明!$A$24:$A$25),IF(B24<=30,FORECAST(B24,参数说明!$B$25:$B$26,参数说明!$A$25:$A$26),IF(B24<=60,FORECAST(B24,参数说明!$B$26:$B$27,参数说明!$A$26:$A$27),IF(B24<=90,FORECAST(B24,参数说明!$B$27:$B$28,参数说明!$A$27:$A$28),IF(B24<=180,FORECAST(B24,参数说明!$B$28:$B$29,参数说明!$A$28:$A$29),FORECAST(B24,参数说明!$B$29:$B$30,参数说明!$A$29:$A$30))))))) -> 40.652174 | D24: =D23+C24 -> 722.06522 | E24: =IF(D24<'等级-经验对照'!$B$4,0,LOOKUP(D24,'等级-经验对照'!$B$4:$B$103,'等级-经验对照'!$A$4:$A$103)) -> 18 | F24: =IF(OR(B24=1,B24=7,B24=30,B24=60,B24=90,B24=180,B24=365),"D"&B24&" / Lv"&E24&" / "&ROUND(D24,0)&" XP","")
A25: =参数说明!$B$8+21 -> 46218 | B25: 21 | C25: =IF(B25=0,0,IF(B25<=7,FORECAST(B25,参数说明!$B$24:$B$25,参数说明!$A$24:$A$25),IF(B25<=30,FORECAST(B25,参数说明!$B$25:$B$26,参数说明!$A$25:$A$26),IF(B25<=60,FORECAST(B25,参数说明!$B$26:$B$27,参数说明!$A$26:$A$27),IF(B25<=90,FORECAST(B25,参数说明!$B$27:$B$28,参数说明!$A$27:$A$28),IF(B25<=180,FORECAST(B25,参数说明!$B$28:$B$29,参数说明!$A$28:$A$29),FORECAST(B25,参数说明!$B$29:$B$30,参数说明!$A$29:$A$30))))))) -> 41.086957 | D25: =D24+C25 -> 763.15217 | E25: =IF(D25<'等级-经验对照'!$B$4,0,LOOKUP(D25,'等级-经验对照'!$B$4:$B$103,'等级-经验对照'!$A$4:$A$103)) -> 18 | F25: =IF(OR(B25=1,B25=7,B25=30,B25=60,B25=90,B25=180,B25=365),"D"&B25&" / Lv"&E25&" / "&ROUND(D25,0)&" XP","")
A26: =参数说明!$B$8+22 -> 46219 | B26: 22 | C26: =IF(B26=0,0,IF(B26<=7,FORECAST(B26,参数说明!$B$24:$B$25,参数说明!$A$24:$A$25),IF(B26<=30,FORECAST(B26,参数说明!$B$25:$B$26,参数说明!$A$25:$A$26),IF(B26<=60,FORECAST(B26,参数说明!$B$26:$B$27,参数说明!$A$26:$A$27),IF(B26<=90,FORECAST(B26,参数说明!$B$27:$B$28,参数说明!$A$27:$A$28),IF(B26<=180,FORECAST(B26,参数说明!$B$28:$B$29,参数说明!$A$28:$A$29),FORECAST(B26,参数说明!$B$29:$B$30,参数说明!$A$29:$A$30))))))) -> 41.521739 | D26: =D25+C26 -> 804.67391 | E26: =IF(D26<'等级-经验对照'!$B$4,0,LOOKUP(D26,'等级-经验对照'!$B$4:$B$103,'等级-经验对照'!$A$4:$A$103)) -> 19 | F26: =IF(OR(B26=1,B26=7,B26=30,B26=60,B26=90,B26=180,B26=365),"D"&B26&" / Lv"&E26&" / "&ROUND(D26,0)&" XP","")
A27: =参数说明!$B$8+23 -> 46220 | B27: 23 | C27: =IF(B27=0,0,IF(B27<=7,FORECAST(B27,参数说明!$B$24:$B$25,参数说明!$A$24:$A$25),IF(B27<=30,FORECAST(B27,参数说明!$B$25:$B$26,参数说明!$A$25:$A$26),IF(B27<=60,FORECAST(B27,参数说明!$B$26:$B$27,参数说明!$A$26:$A$27),IF(B27<=90,FORECAST(B27,参数说明!$B$27:$B$28,参数说明!$A$27:$A$28),IF(B27<=180,FORECAST(B27,参数说明!$B$28:$B$29,参数说明!$A$28:$A$29),FORECAST(B27,参数说明!$B$29:$B$30,参数说明!$A$29:$A$30))))))) -> 41.956522 | D27: =D26+C27 -> 846.63043 | E27: =IF(D27<'等级-经验对照'!$B$4,0,LOOKUP(D27,'等级-经验对照'!$B$4:$B$103,'等级-经验对照'!$A$4:$A$103)) -> 20 | F27: =IF(OR(B27=1,B27=7,B27=30,B27=60,B27=90,B27=180,B27=365),"D"&B27&" / Lv"&E27&" / "&ROUND(D27,0)&" XP","")
A28: =参数说明!$B$8+24 -> 46221 | B28: 24 | C28: =IF(B28=0,0,IF(B28<=7,FORECAST(B28,参数说明!$B$24:$B$25,参数说明!$A$24:$A$25),IF(B28<=30,FORECAST(B28,参数说明!$B$25:$B$26,参数说明!$A$25:$A$26),IF(B28<=60,FORECAST(B28,参数说明!$B$26:$B$27,参数说明!$A$26:$A$27),IF(B28<=90,FORECAST(B28,参数说明!$B$27:$B$28,参数说明!$A$27:$A$28),IF(B28<=180,FORECAST(B28,参数说明!$B$28:$B$29,参数说明!$A$28:$A$29),FORECAST(B28,参数说明!$B$29:$B$30,参数说明!$A$29:$A$30))))))) -> 42.391304 | D28: =D27+C28 -> 889.02174 | E28: =IF(D28<'等级-经验对照'!$B$4,0,LOOKUP(D28,'等级-经验对照'!$B$4:$B$103,'等级-经验对照'!$A$4:$A$103)) -> 20 | F28: =IF(OR(B28=1,B28=7,B28=30,B28=60,B28=90,B28=180,B28=365),"D"&B28&" / Lv"&E28&" / "&ROUND(D28,0)&" XP","")
A29: =参数说明!$B$8+25 -> 46222 | B29: 25 | C29: =IF(B29=0,0,IF(B29<=7,FORECAST(B29,参数说明!$B$24:$B$25,参数说明!$A$24:$A$25),IF(B29<=30,FORECAST(B29,参数说明!$B$25:$B$26,参数说明!$A$25:$A$26),IF(B29<=60,FORECAST(B29,参数说明!$B$26:$B$27,参数说明!$A$26:$A$27),IF(B29<=90,FORECAST(B29,参数说明!$B$27:$B$28,参数说明!$A$27:$A$28),IF(B29<=180,FORECAST(B29,参数说明!$B$28:$B$29,参数说明!$A$28:$A$29),FORECAST(B29,参数说明!$B$29:$B$30,参数说明!$A$29:$A$30))))))) -> 42.826087 | D29: =D28+C29 -> 931.84783 | E29: =IF(D29<'等级-经验对照'!$B$4,0,LOOKUP(D29,'等级-经验对照'!$B$4:$B$103,'等级-经验对照'!$A$4:$A$103)) -> 21 | F29: =IF(OR(B29=1,B29=7,B29=30,B29=60,B29=90,B29=180,B29=365),"D"&B29&" / Lv"&E29&" / "&ROUND(D29,0)&" XP","")
A30: =参数说明!$B$8+26 -> 46223 | B30: 26 | C30: =IF(B30=0,0,IF(B30<=7,FORECAST(B30,参数说明!$B$24:$B$25,参数说明!$A$24:$A$25),IF(B30<=30,FORECAST(B30,参数说明!$B$25:$B$26,参数说明!$A$25:$A$26),IF(B30<=60,FORECAST(B30,参数说明!$B$26:$B$27,参数说明!$A$26:$A$27),IF(B30<=90,FORECAST(B30,参数说明!$B$27:$B$28,参数说明!$A$27:$A$28),IF(B30<=180,FORECAST(B30,参数说明!$B$28:$B$29,参数说明!$A$28:$A$29),FORECAST(B30,参数说明!$B$29:$B$30,参数说明!$A$29:$A$30))))))) -> 43.26087 | D30: =D29+C30 -> 975.1087 | E30: =IF(D30<'等级-经验对照'!$B$4,0,LOOKUP(D30,'等级-经验对照'!$B$4:$B$103,'等级-经验对照'!$A$4:$A$103)) -> 22 | F30: =IF(OR(B30=1,B30=7,B30=30,B30=60,B30=90,B30=180,B30=365),"D"&B30&" / Lv"&E30&" / "&ROUND(D30,0)&" XP","")
A31: =参数说明!$B$8+27 -> 46224 | B31: 27 | C31: =IF(B31=0,0,IF(B31<=7,FORECAST(B31,参数说明!$B$24:$B$25,参数说明!$A$24:$A$25),IF(B31<=30,FORECAST(B31,参数说明!$B$25:$B$26,参数说明!$A$25:$A$26),IF(B31<=60,FORECAST(B31,参数说明!$B$26:$B$27,参数说明!$A$26:$A$27),IF(B31<=90,FORECAST(B31,参数说明!$B$27:$B$28,参数说明!$A$27:$A$28),IF(B31<=180,FORECAST(B31,参数说明!$B$28:$B$29,参数说明!$A$28:$A$29),FORECAST(B31,参数说明!$B$29:$B$30,参数说明!$A$29:$A$30))))))) -> 43.695652 | D31: =D30+C31 -> 1018.8043 | E31: =IF(D31<'等级-经验对照'!$B$4,0,LOOKUP(D31,'等级-经验对照'!$B$4:$B$103,'等级-经验对照'!$A$4:$A$103)) -> 22 | F31: =IF(OR(B31=1,B31=7,B31=30,B31=60,B31=90,B31=180,B31=365),"D"&B31&" / Lv"&E31&" / "&ROUND(D31,0)&" XP","")
A32: =参数说明!$B$8+28 -> 46225 | B32: 28 | C32: =IF(B32=0,0,IF(B32<=7,FORECAST(B32,参数说明!$B$24:$B$25,参数说明!$A$24:$A$25),IF(B32<=30,FORECAST(B32,参数说明!$B$25:$B$26,参数说明!$A$25:$A$26),IF(B32<=60,FORECAST(B32,参数说明!$B$26:$B$27,参数说明!$A$26:$A$27),IF(B32<=90,FORECAST(B32,参数说明!$B$27:$B$28,参数说明!$A$27:$A$28),IF(B32<=180,FORECAST(B32,参数说明!$B$28:$B$29,参数说明!$A$28:$A$29),FORECAST(B32,参数说明!$B$29:$B$30,参数说明!$A$29:$A$30))))))) -> 44.130435 | D32: =D31+C32 -> 1062.9348 | E32: =IF(D32<'等级-经验对照'!$B$4,0,LOOKUP(D32,'等级-经验对照'!$B$4:$B$103,'等级-经验对照'!$A$4:$A$103)) -> 23 | F32: =IF(OR(B32=1,B32=7,B32=30,B32=60,B32=90,B32=180,B32=365),"D"&B32&" / Lv"&E32&" / "&ROUND(D32,0)&" XP","")
A33: =参数说明!$B$8+29 -> 46226 | B33: 29 | C33: =IF(B33=0,0,IF(B33<=7,FORECAST(B33,参数说明!$B$24:$B$25,参数说明!$A$24:$A$25),IF(B33<=30,FORECAST(B33,参数说明!$B$25:$B$26,参数说明!$A$25:$A$26),IF(B33<=60,FORECAST(B33,参数说明!$B$26:$B$27,参数说明!$A$26:$A$27),IF(B33<=90,FORECAST(B33,参数说明!$B$27:$B$28,参数说明!$A$27:$A$28),IF(B33<=180,FORECAST(B33,参数说明!$B$28:$B$29,参数说明!$A$28:$A$29),FORECAST(B33,参数说明!$B$29:$B$30,参数说明!$A$29:$A$30))))))) -> 44.565217 | D33: =D32+C33 -> 1107.5 | E33: =IF(D33<'等级-经验对照'!$B$4,0,LOOKUP(D33,'等级-经验对照'!$B$4:$B$103,'等级-经验对照'!$A$4:$A$103)) -> 24 | F33: =IF(OR(B33=1,B33=7,B33=30,B33=60,B33=90,B33=180,B33=365),"D"&B33&" / Lv"&E33&" / "&ROUND(D33,0)&" XP","")
A34: =参数说明!$B$8+30 -> 46227 | B34: 30 | C34: =IF(B34=0,0,IF(B34<=7,FORECAST(B34,参数说明!$B$24:$B$25,参数说明!$A$24:$A$25),IF(B34<=30,FORECAST(B34,参数说明!$B$25:$B$26,参数说明!$A$25:$A$26),IF(B34<=60,FORECAST(B34,参数说明!$B$26:$B$27,参数说明!$A$26:$A$27),IF(B34<=90,FORECAST(B34,参数说明!$B$27:$B$28,参数说明!$A$27:$A$28),IF(B34<=180,FORECAST(B34,参数说明!$B$28:$B$29,参数说明!$A$28:$A$29),FORECAST(B34,参数说明!$B$29:$B$30,参数说明!$A$29:$A$30))))))) -> 45 | D34: =D33+C34 -> 1152.5 | E34: =IF(D34<'等级-经验对照'!$B$4,0,LOOKUP(D34,'等级-经验对照'!$B$4:$B$103,'等级-经验对照'!$A$4:$A$103)) -> 25 | F34: =IF(OR(B34=1,B34=7,B34=30,B34=60,B34=90,B34=180,B34=365),"D"&B34&" / Lv"&E34&" / "&ROUND(D34,0)&" XP","") -> D30 / Lv25 / 1153 XP
A35: =参数说明!$B$8+31 -> 46228 | B35: 31 | C35: =IF(B35=0,0,IF(B35<=7,FORECAST(B35,参数说明!$B$24:$B$25,参数说明!$A$24:$A$25),IF(B35<=30,FORECAST(B35,参数说明!$B$25:$B$26,参数说明!$A$25:$A$26),IF(B35<=60,FORECAST(B35,参数说明!$B$26:$B$27,参数说明!$A$26:$A$27),IF(B35<=90,FORECAST(B35,参数说明!$B$27:$B$28,参数说明!$A$27:$A$28),IF(B35<=180,FORECAST(B35,参数说明!$B$28:$B$29,参数说明!$A$28:$A$29),FORECAST(B35,参数说明!$B$29:$B$30,参数说明!$A$29:$A$30))))))) -> 45.333333 | D35: =D34+C35 -> 1197.8333 | E35: =IF(D35<'等级-经验对照'!$B$4,0,LOOKUP(D35,'等级-经验对照'!$B$4:$B$103,'等级-经验对照'!$A$4:$A$103)) -> 25 | F35: =IF(OR(B35=1,B35=7,B35=30,B35=60,B35=90,B35=180,B35=365),"D"&B35&" / Lv"&E35&" / "&ROUND(D35,0)&" XP","")
A36: =参数说明!$B$8+32 -> 46229 | B36: 32 | C36: =IF(B36=0,0,IF(B36<=7,FORECAST(B36,参数说明!$B$24:$B$25,参数说明!$A$24:$A$25),IF(B36<=30,FORECAST(B36,参数说明!$B$25:$B$26,参数说明!$A$25:$A$26),IF(B36<=60,FORECAST(B36,参数说明!$B$26:$B$27,参数说明!$A$26:$A$27),IF(B36<=90,FORECAST(B36,参数说明!$B$27:$B$28,参数说明!$A$27:$A$28),IF(B36<=180,FORECAST(B36,参数说明!$B$28:$B$29,参数说明!$A$28:$A$29),FORECAST(B36,参数说明!$B$29:$B$30,参数说明!$A$29:$A$30))))))) -> 45.666667 | D36: =D35+C36 -> 1243.5 | E36: =IF(D36<'等级-经验对照'!$B$4,0,LOOKUP(D36,'等级-经验对照'!$B$4:$B$103,'等级-经验对照'!$A$4:$A$103)) -> 25 | F36: =IF(OR(B36=1,B36=7,B36=30,B36=60,B36=90,B36=180,B36=365),"D"&B36&" / Lv"&E36&" / "&ROUND(D36,0)&" XP","")
A37: =参数说明!$B$8+33 -> 46230 | B37: 33 | C37: =IF(B37=0,0,IF(B37<=7,FORECAST(B37,参数说明!$B$24:$B$25,参数说明!$A$24:$A$25),IF(B37<=30,FORECAST(B37,参数说明!$B$25:$B$26,参数说明!$A$25:$A$26),IF(B37<=60,FORECAST(B37,参数说明!$B$26:$B$27,参数说明!$A$26:$A$27),IF(B37<=90,FORECAST(B37,参数说明!$B$27:$B$28,参数说明!$A$27:$A$28),IF(B37<=180,FORECAST(B37,参数说明!$B$28:$B$29,参数说明!$A$28:$A$29),FORECAST(B37,参数说明!$B$29:$B$30,参数说明!$A$29:$A$30))))))) -> 46 | D37: =D36+C37 -> 1289.5 | E37: =IF(D37<'等级-经验对照'!$B$4,0,LOOKUP(D37,'等级-经验对照'!$B$4:$B$103,'等级-经验对照'!$A$4:$A$103)) -> 26 | F37: =IF(OR(B37=1,B37=7,B37=30,B37=60,B37=90,B37=180,B37=365),"D"&B37&" / Lv"&E37&" / "&ROUND(D37,0)&" XP","")
A38: =参数说明!$B$8+34 -> 46231 | B38: 34 | C38: =IF(B38=0,0,IF(B38<=7,FORECAST(B38,参数说明!$B$24:$B$25,参数说明!$A$24:$A$25),IF(B38<=30,FORECAST(B38,参数说明!$B$25:$B$26,参数说明!$A$25:$A$26),IF(B38<=60,FORECAST(B38,参数说明!$B$26:$B$27,参数说明!$A$26:$A$27),IF(B38<=90,FORECAST(B38,参数说明!$B$27:$B$28,参数说明!$A$27:$A$28),IF(B38<=180,FORECAST(B38,参数说明!$B$28:$B$29,参数说明!$A$28:$A$29),FORECAST(B38,参数说明!$B$29:$B$30,参数说明!$A$29:$A$30))))))) -> 46.333333 | D38: =D37+C38 -> 1335.8333 | E38: =IF(D38<'等级-经验对照'!$B$4,0,LOOKUP(D38,'等级-经验对照'!$B$4:$B$103,'等级-经验对照'!$A$4:$A$103)) -> 26 | F38: =IF(OR(B38=1,B38=7,B38=30,B38=60,B38=90,B38=180,B38=365),"D"&B38&" / Lv"&E38&" / "&ROUND(D38,0)&" XP","")
A39: =参数说明!$B$8+35 -> 46232 | B39: 35 | C39: =IF(B39=0,0,IF(B39<=7,FORECAST(B39,参数说明!$B$24:$B$25,参数说明!$A$24:$A$25),IF(B39<=30,FORECAST(B39,参数说明!$B$25:$B$26,参数说明!$A$25:$A$26),IF(B39<=60,FORECAST(B39,参数说明!$B$26:$B$27,参数说明!$A$26:$A$27),IF(B39<=90,FORECAST(B39,参数说明!$B$27:$B$28,参数说明!$A$27:$A$28),IF(B39<=180,FORECAST(B39,参数说明!$B$28:$B$29,参数说明!$A$28:$A$29),FORECAST(B39,参数说明!$B$29:$B$30,参数说明!$A$29:$A$30))))))) -> 46.666667 | D39: =D38+C39 -> 1382.5 | E39: =IF(D39<'等级-经验对照'!$B$4,0,LOOKUP(D39,'等级-经验对照'!$B$4:$B$103,'等级-经验对照'!$A$4:$A$103)) -> 26 | F39: =IF(OR(B39=1,B39=7,B39=30,B39=60,B39=90,B39=180,B39=365),"D"&B39&" / Lv"&E39&" / "&ROUND(D39,0)&" XP","")
A40: =参数说明!$B$8+36 -> 46233 | B40: 36 | C40: =IF(B40=0,0,IF(B40<=7,FORECAST(B40,参数说明!$B$24:$B$25,参数说明!$A$24:$A$25),IF(B40<=30,FORECAST(B40,参数说明!$B$25:$B$26,参数说明!$A$25:$A$26),IF(B40<=60,FORECAST(B40,参数说明!$B$26:$B$27,参数说明!$A$26:$A$27),IF(B40<=90,FORECAST(B40,参数说明!$B$27:$B$28,参数说明!$A$27:$A$28),IF(B40<=180,FORECAST(B40,参数说明!$B$28:$B$29,参数说明!$A$28:$A$29),FORECAST(B40,参数说明!$B$29:$B$30,参数说明!$A$29:$A$30))))))) -> 47 | D40: =D39+C40 -> 1429.5 | E40: =IF(D40<'等级-经验对照'!$B$4,0,LOOKUP(D40,'等级-经验对照'!$B$4:$B$103,'等级-经验对照'!$A$4:$A$103)) -> 27 | F40: =IF(OR(B40=1,B40=7,B40=30,B40=60,B40=90,B40=180,B40=365),"D"&B40&" / Lv"&E40&" / "&ROUND(D40,0)&" XP","")
A41: =参数说明!$B$8+37 -> 46234 | B41: 37 | C41: =IF(B41=0,0,IF(B41<=7,FORECAST(B41,参数说明!$B$24:$B$25,参数说明!$A$24:$A$25),IF(B41<=30,FORECAST(B41,参数说明!$B$25:$B$26,参数说明!$A$25:$A$26),IF(B41<=60,FORECAST(B41,参数说明!$B$26:$B$27,参数说明!$A$26:$A$27),IF(B41<=90,FORECAST(B41,参数说明!$B$27:$B$28,参数说明!$A$27:$A$28),IF(B41<=180,FORECAST(B41,参数说明!$B$28:$B$29,参数说明!$A$28:$A$29),FORECAST(B41,参数说明!$B$29:$B$30,参数说明!$A$29:$A$30))))))) -> 47.333333 | D41: =D40+C41 -> 1476.8333 | E41: =IF(D41<'等级-经验对照'!$B$4,0,LOOKUP(D41,'等级-经验对照'!$B$4:$B$103,'等级-经验对照'!$A$4:$A$103)) -> 27 | F41: =IF(OR(B41=1,B41=7,B41=30,B41=60,B41=90,B41=180,B41=365),"D"&B41&" / Lv"&E41&" / "&ROUND(D41,0)&" XP","")
...

Sheet 参数说明
A1: 参数说明
A3: 参数 | B3: 值
A4: 等级上限 | B4: 100
A5: 基础题型 XP | B5: 10
A6: 普通用户每日 level | B6: 3
A7: 普通用户每日 XP | B7: =B5*B6 -> 30
A8: 新增日期 | B8: 46197
A9: 曲线天数 | B9: 365
A12: 等级锚点 | B12: 累计经验 | C12: 说明
A13: 0 | B13: 0 | C13: 初始等级
A14: 3 | B14: 30 | C14: 首日约到 Lv3
A15: 10 | B15: 225 | C15: 7 日约到 Lv10
A16: 25 | B16: 1150 | C16: 30 日约到 Lv25
A17: 37 | B17: 2650 | C17: 60 日约到 Lv37
A18: 45 | B18: 4450 | C18: 90 日约到 Lv45
A19: 65 | B19: 10995 | C19: 180 日约到 Lv65
A20: 100 | B20: 27600 | C20: 365 日约到 Lv100
A23: 每日 XP 留存天数 | B23: 当日 XP | C23: 说明
A24: 1 | B24: 30 | C24: 首日约 3 个基础学习行为
A25: 7 | B25: 35 | C25: 首周形成轻量学习节奏
A26: 30 | B26: 45 | C26: 30 日后课程完成数和进阶题占比提升
A27: 60 | B27: 55 | C27: 两个月后学习习惯更稳定
A28: 90 | B28: 65 | C28: 季度留存用户更愿意做口语/听力
A29: 180 | B29: 80 | C29: 半年留存用户学习深度继续增加
A30: 365 | B30: 100 | C30: 年度留存用户进入稳定高频学习
A33: 说明
A34: 1 | B34: 修改 B4:B9、等级锚点或每日 XP 留存曲线锚点，会影响前两张表。
A35: 2 | B35: 等级页通过等级锚点线性插值生成累计经验，并四舍五入到 5 的倍数。
A36: 3 | B36: 曲线页按新增日期起算，当日 XP 随留存天数分段增长，累计经验为每日 XP 累加。
A37: 4 | B37: 多邻国用 XP 做即时反馈，但长期成长会受学习习惯、任务、活动影响；Pinu 第一版先只建课程 XP 地基。
A38: 5 | B38: 第一版暂不引入 Coins、任务 XP、倍卡 XP，避免早期经济系统过重。
A39: 6 | B39: 如未来任务、倍卡或活动使 XP 长期膨胀，应优先上调中后段等级锚点。
